Workbook
Name Slicer_Customer_Segment: #N/A
Name Slicer_Product: #N/A
Name Slicer_State1: #N/A

Sheet Raw_Data
A1: Order_ID | B1: Order_Date | C1: Customer_ID | D1: State | E1: Customer_Segment | F1: Product | G1: Category | H1: Quantity | I1: Unit_Price_INR | J1: Discount | K1: Sales_INR | L1: Cost_INR | M1: Profit_INR | N1: Payment_Mode
A2: ORD1002 | B2: 2025-02-22 | C2: CUST170 | D2: Haryana | E2: Small Business | F2: Monitor | G2: Electronics | H2: 3 | I2: 9600 | J2: 0.05 | K2: 27360 | L2: 20869.69 | M2: 6490.31 | N2: Net Banking
A3: ORD1003 | B3: 2025-11-05 | C3: CUST104 | D3: West Bengal | E3: Consumer | F3: Laptop | G3: Electronics | H3: 1 | I3: 46500 | J3: 0.05 | K3: 44175 | L3: 33783.75 | M3: 10391.25 | N3: Cash
A4: ORD1004 | B4: 2025-01-04 | C4: CUST121 | D4: Rajasthan | E4: Corporate | F4: Tablet | G4: Electronics | H4: 4 | I4: 23200 | J4: 0.1 | K4: 83520 | L4: 78127.03 | M4: 5392.97 | N4: Debit Card
A5: ORD1005 | B5: 2025-02-19 | C5: CUST146 | D5: Gujarat | E5: Small Business | F5: Keyboard | G5: Accessories | H5: 3 | I5: 2100 | J5: 0 | K5: 6300 | L5: 4400.86 | M5: 1899.14 | N5: Debit Card
A6: ORD1006 | B6: 2025-07-13 | C6: CUST111 | D6: West Bengal | E6: Corporate | F6: Laptop | G6: Electronics | H6: 4 | I6: 82300 | J6: 0 | K6: 329200 | L6: 287925.94 | M6: 41274.06 | N6: Cash
A7: ORD1007 | B7: 2025-04-27 | C7: CUST138 | D7: Haryana | E7: Consumer | F7: Printer | G7: Office Equipment | H7: 2 | I7: 21700 | J7: 0 | K7: 43400 | L7: 29909.76 | M7: 13490.24 | N7: UPI
A8: ORD1008 | B8: 2025-07-01 | C8: CUST127 | D8: Karnataka | E8: Small Business | F8: Tablet | G8: Electronics | H8: 4 | I8: 26200 | J8: 0.1 | K8: 94320 | L8: 74673.23 | M8: 19646.77 | N8: UPI
A9: ORD1009 | B9: 2025-05-19 | C9: CUST172 | D9: Maharashtra | E9: Small Business | F9: Keyboard | G9: Accessories | H9: 2 | I9: 4200 | J9: 0.05 | K9: 7980 | L9: 6488.6 | M9: 1491.4 | N9: Debit Card
A10: ORD1010 | B10: 2025-02-03 | C10: CUST128 | D10: Tamil Nadu | E10: Small Business | F10: Laptop | G10: Electronics | H10: 1 | I10: 56700 | J10: 0.1 | K10: 51030 | L10: 43105.21 | M10: 7924.79 | N10: Debit Card
A11: ORD1011 | B11: 2025-11-26 | C11: CUST159 | D11: Uttar Pradesh | E11: Corporate | F11: Mouse | G11: Accessories | H11: 4 | I11: 2500 | J11: 0.15 | K11: 8500 | L11: 8569.37 | M11: -69.37 | N11: Credit Card
A12: ORD1012 | B12: 2025-08-08 | C12: CUST175 | D12: Rajasthan | E12: Corporate | F12: Mouse | G12: Accessories | H12: 5 | I12: 2800 | J12: 0.1 | K12: 12600 | L12: 11611.64 | M12: 988.36 | N12: Credit Card
A13: ORD1013 | B13: 2025-02-26 | C13: CUST120 | D13: Uttar Pradesh | E13: Small Business | F13: Keyboard | G13: Accessories | H13: 4 | I13: 4000 | J13: 0 | K13: 16000 | L13: 13298.5 | M13: 2701.5 | N13: Net Banking
... A201: ORD1201 | B201: 2025-03-23 | C201: CUST142 | D201: Tamil Nadu | E201: Small Business | F201: Headphones | G201: Accessories | H201: 5 | I201: 3600 | J201: 0.15 | K201: 15300 | L201: 13133.77 | M201: 2166.23 | N201: Debit Card

Sheet Analysis
A1: Metric | B1: Values
A2: Total Sales | B2: =SUM(Raw_Data!K:K) -> 11394020 | D2: Find the Product for a given Order ID using XLOOKUP
A4: Total Costs | B4: =SUM(Raw_Data!L:L) -> 9647061.3 | D4: Order ID | E4: Product
D5: ORD1138 | E5: =_xlfn.XLOOKUP(D5,Raw_Data!A:A,Raw_Data!F:F,"Not found",0) -> Keyboard
A6: Total Profit | B6: =B2-B4 -> 1746958.7
A8: Total Quantity | B8: =SUM(Raw_Data!H:H) -> 592 | D8: Find the Customer Segment for a given Customer ID using XLOOKUP
A10: Total Orders | B10: =COUNTA(Raw_Data!A:A) -> 201 | D10: Customer ID | E10: Cus. Segment
D11: CUST135 | E11: =_xlfn.XLOOKUP(D11,Raw_Data!C:C,Raw_Data!E:E,"Not Found",0) -> Small Business
A12: Average Order Value | B12: =AVERAGE(Raw_Data!K:K) -> 56970.1
A14: Profit Margin | B14: =B6/B2 -> 0.15332242 | D14: Find the Sales for a given Order ID using VLOOKUP
D16: Order ID | E16: Sales
A17: Find the average Profit for a given State using AVERAGEIF | D17: ORD1138 | E17: =VLOOKUP(D17,Raw_Data!A:N,MATCH(Raw_Data!K1,Raw_Data!A1:N1,0),0) -> 7225
A19: State | B19: Avg.Profit | D19: Find the Profit for a given Order ID using VLOOKUP and MATCH
A20: Gujarat | B20: =AVERAGEIF(Raw_Data!D:D,Raw_Data!D5,Raw_Data!M:M) -> 11477.181
A21: Maharashtra | B21: =AVERAGEIF(Raw_Data!D:D,Raw_Data!D6,Raw_Data!M:M) -> 11415.528 | D21: Order ID | E21: Profit
A22: West Bengal | B22: =AVERAGEIF(Raw_Data!D:D,Raw_Data!D7,Raw_Data!M:M) -> 6952.5868 | D22: ORD1056 | E22: =VLOOKUP(D22,Raw_Data!A:N,MATCH(Raw_Data!M1,Raw_Data!A1:N1,0),0) -> 2085.79
A25: Identify whether an order is Profitable or Loss-making using IF | D25: Find total Sales for a given State using SUMIF
A27: Profit | B27: Status | D27: State | E27: Sales
A28: 19646.77 | B28: =IF(A28>200,"Profitable","Loss") -> Profitable | D28: Delhi | E28: =SUMIF(Raw_Data!D:D,Analysis!D28,Raw_Data!K:K) -> 735330
A29: 206.66 | B29: =IF(A29>200,"Profitable","Loss") -> Profitable | D29: Gujarat | E29: =SUMIF(Raw_Data!D:D,Analysis!D29,Raw_Data!K:K) -> 1664620
A30: -110.14 | B30: =IF(A30>200,"Profitable","Loss") -> Loss
A33: Categorize orders based on Profit using IFS | D33: Find total Sales for a given State and Customer Segment using SUMIFS
A34: Profit | B34: Status | D34: State | E34: Cus. Segment | F34: Sales
A35: 10000 | B35: {=_xlfn.IFS(A35>9000,"High Profit",A35>=5000,"Medium Profit",A35<5000,"Low Profit")} -> High Profit | D35: Delhi | E35: Small Business | F35: =SUMIFS(Raw_Data!K:K,Raw_Data!D:D,Raw_Data!D15,Raw_Data!E:E,Raw_Data!E2) -> 507180
A36: 5000 | B36: {=_xlfn.IFS(A36>9000,"High Profit",A36>=5000,"Medium Profit",A36<5000,"Low Profit")} -> Medium Profit | D36: West Bengal | E36: Consumer | F36: =SUMIFS(Raw_Data!K:K,Raw_Data!D:D,Raw_Data!D16,Raw_Data!E:E,Raw_Data!E3) -> 75885
A37: 4000 | B37: {=_xlfn.IFS(A37>9000,"High Profit",A37>=5000,"Medium Profit",A37<5000,"Low Profit")} -> Low Profit
D39: Count the number of orders for a given State using COUNTIF
D41: State | E41: Number of Orders
D42: West Bengal | E42: =COUNTIF(Raw_Data!D:D,Analysis!D42) -> 21
D43: Gujarat | E43: =COUNTIF(Raw_Data!D:D,Analysis!D43) -> 23
D44: Delhi | E44: =COUNTIF(Raw_Data!D:D,Analysis!D44) -> 14

Sheet Pivot_Analysis
A1: State-wise Sales
A3: State | B3: Sum of Sales_INR
A4: Gujarat | B4: 1664620
A5: Karnataka | B5: 1564060
A6: Rajasthan | B6: 1420115
A7: Uttar Pradesh | B7: 1340555
A8: Haryana | B8: 1303140
A9: West Bengal | B9: 1210015
A10: Tamil Nadu | B10: 998980
A11: Delhi | B11: 735330
A12: Maharashtra | B12: 724605
A13: Punjab | B13: 432600
A14: Grand Total | B14: 11394020
A17: Product-wise Profit
A19: Product | B19: Sum of Profit_INR
A20: Laptop | B20: 828751.19
A21: Tablet | B21: 423513.08
A22: Monitor | B22: 229837.17
A23: Printer | B23: 116910.72
A24: Webcam | B24: 58826.35
A25: Headphones | B25: 47017.17
A26: Keyboard | B26: 29543.03
A27: Mouse | B27: 12559.99
A28: Grand Total | B28: 1746958.7
A31: State-wise Profit
A33: State | B33: Sum of Profit_INR
A34: Gujarat | B34: 263975.17
A35: Karnataka | B35: 255756.68
A36: West Bengal | B36: 239726.08
A37: Rajasthan | B37: 230110.46
A38: Haryana | B38: 194672.43
A39: Uttar Pradesh | B39: 191388.01
A40: Tamil Nadu | B40: 143025.75
A41: Delhi | B41: 94133.21
A42: Maharashtra | B42: 81378.66
A43: Punjab | B43: 52792.25
A44: Grand Total | B44: 1746958.7
A47: Segment-wise Sales
A49: Customer_Segment | B49: Sum of Sales_INR
A50: Consumer | B50: 2136655
...

Sheet Business Insights
B2: Business Question | C2: Finding | D2: Business Insight
B3: Which state has the highest sales? | C3: Gujarat – ₹1,664,620 | D3: Gujarat has the highest sales among all states, indicating strong sales performance in this region.
B5: Which state has the highest profit? | C5: Gujarat – ₹2,63,975.17 | D5: Gujarat generates the highest profit among all states, indicating strong profitability in this region.
B7: Which product generates the highest profit? | C7: Laptop – ₹8,28,751.19 | D7: Laptop generates the highest profit among all products, indicating strong profitability and customer demand.
B9: Which customer segment generates the highest sales? | C9: Small Business – ₹53,69,040 | D9: Small Business generates the highest sales among all customer segments, indicating strong demand from this segment.

Sheet Dasboard
A1: SALES DATA ANALYSIS DASHBOARD
D7: SALES DATA ANALYSIS DASHBOARD
D9: Sales Performance & Business Insights
D14: Total Sales | H14: Total Cost | L14: Total Profit
D16: =SUM(Raw_Data!K:K) -> 11394020 | H16: =SUM(Raw_Data!L:L) -> 9647061.3 | L16: =SUM(Raw_Data!M:M) -> 1746958.7
D20: Total Orders | H20: Total Quantity | L20: Profit Margin
D22: =COUNTA(Raw_Data!A:A) -> 201 | H22: =SUM(Raw_Data!H:H) -> 592 | L22: =L16/D16 -> 0.15332242
